.TH std::rethrow_if_nested 3 "Nov 25 2015" "2.1 | http://cppreference.com" "C++ Standard Libary"
.SH NAME
std::rethrow_if_nested \- std::rethrow_if_nested

.SH Synopsis
   Defined in header <exception>
   template< class E >                    \fI(since C++11)\fP
   void rethrow_if_nested( const E& e );

   If the dynamic type (the most derived type) of the object referenced by e is
   publicly and unambiguously derived from std::nested_exception, extracts and throws
   the nested exception as if by calling dynamic_cast<const
   std::nested_exception&>(e).rethrow_nested(). Otherwise, does nothing.

.SH Parameters

   e - the exception object to rethrow

.SH Return value

   \fI(none)\fP

.SH Possible implementation

   template <class T>
   void rethrow_if_nested(const T& e,
                          std::enable_if_t<std::is_polymorphic<T>::value>* = 0)
   {
       if(auto nep = dynamic_cast<const std::nested_exception*>(&e))
           nep->rethrow_nested();
   }
    
   template <class T>
   void rethrow_if_nested(const T&,
                          std::enable_if_t<!std::is_polymorphic<T>::value>* = 0)
   {
   }

.SH Example

   

   Demonstrates construction and recursion through a nested exception object

   
// Run this code

 #include <iostream>
 #include <stdexcept>
 #include <exception>
 #include <string>
 #include <fstream>
  
 // prints the explanatory string of an exception. If the exception is nested,
 // recurses to print the explanatory of the exception it holds
 void print_exception(const std::exception& e, int level =  0)
 {
     std::cerr << std::string(level, ' ') << "exception: " << e.what() << '\\n';
     try {
         std::rethrow_if_nested(e);
     } catch(const std::exception& e) {
         print_exception(e, level+1);
     } catch(...) {}
 }
  
 // sample function that catches an exception and wraps it in a nested exception
 void open_file(const std::string& s)
 {
     try {
         std::ifstream file(s);
         file.exceptions(std::ios_base::failbit);
     } catch(...) {
         std::throw_with_nested( std::runtime_error("Couldn't open " + s) );
     }
 }
  
 // sample function that catches an exception and wraps it in a nested exception
 void run()
 {
     try {
         open_file("nonexistent.file");
     } catch(...) {
         std::throw_with_nested( std::runtime_error("run() failed") );
     }
 }
  
 // runs the sample function above and prints the caught exception
 int main()
 {
     try {
         run();
     } catch(const std::exception& e) {
         print_exception(e);
     }
 }

.SH Output:

 exception: run() failed
  exception: Couldn't open nonexistent.file
   exception: basic_ios::clear

.SH See also

   nested_exception  a mixin type to capture and store current exceptions
   \fI(C++11)\fP           \fI(class)\fP 
   throw_with_nested throws its argument with std::nested_exception mixed in
   \fI(C++11)\fP           \fI(function template)\fP 
